<?xml version="1.0"?>

<!-- ANGLES - RADIAN -->

<!--Start with the robot name-->
<robot name="test_parrot">

    <material name="blue">
        <color rgba="0 0 0.5 1" />
    </material>

    <material name="green">
        <color rgba="0 0.5 0 1" />
    </material>

    <!--Creating a link-->
    <link name="base_link">
        <visual>
            <geometry>
                <!--the box is 60cm long and 40cm wide-->
                <box size="0.6 0.4 0.2" />
            </geometry>
            <!--Translation & Rotation Along xyz, rpy(roll pitch yaw)-->
            <!--0.1 - offset centre of box to botttom face-->
            <origin xyz="0 0 0.1" rpy="0 0 0" />
            <material name="blue" />
        </visual>
    </link>    

    <link name="second_link">
        <visual>
            <geometry>
                <cylinder radius="0.2" length="0.3" />
            </geometry>
            <origin xyz="0 0 0.15" rpy="0 0 0" />
            <material name="green" />
        </visual>
    </link>    

    <joint name="base_second_joint" type="revolute">
        <parent link="base_link"/>
        <child link="second_link"/>
        <origin xyz="0 0 0.2" rpy="0 0 0" />

        <!-- Specofy Axis of Rotation-->
        <axis xyz="0 0 1" />

        <!-- Min Max Joint Angle Value-->
        <limit lower="-1.57" upper="1.57" velocity="100" effort="100" />
    </joint>

</robot>